<?xml version="1.0" encoding="utf-8"?>
<!-- This URDF was automatically created by SolidWorks to URDF Exporter! Originally created by Stephen Brawner (brawner@gmail.com) 
     Commit Version: 1.6.0-4-g7f85cfe  Build Version: 1.6.7995.38578
     For more information, please see http://wiki.ros.org/sw_urdf_exporter -->
<robot
  name="Conceptual Mechanism Assembly2">
  <link
    name="base_link">
    <inertial>
      <origin
        xyz="4.3535E-18 -0.045356 0.41"
        rpy="0 0 0" />
      <mass
        value="0.15808" />
      <inertia
        ixx="0.00012329"
        ixy="-2.5259E-20"
        ixz="8.3821E-23"
        iyy="0.00052039"
        iyz="2.4384E-21"
        izz="0.00063313" />
    </inertial>
    <visual>
      <origin
        xyz="0 0 0"
        rpy="0 0 0" />
      <geometry>
        <mesh
          filename="package://Conceptual Mechanism Assembly2/meshes/base_link.STL" />
      </geometry>
      <material
        name="">
        <color
          rgba="0.79216 0.81961 0.93333 1" />
      </material>
    </visual>
    <collision>
      <origin
        xyz="0 0 0"
        rpy="0 0 0" />
      <geometry>
        <mesh
          filename="package://Conceptual Mechanism Assembly2/meshes/base_link.STL" />
      </geometry>
    </collision>
  </link>
  <link
    name="vertical">
    <inertial>
      <origin
        xyz="-0.0097307 0.425 0.0013529"
        rpy="0 0 0" />
      <mass
        value="1.2121" />
      <inertia
        ixx="0.12949"
        ixy="5.6735E-18"
        ixz="-1.5957E-05"
        iyy="0.0019942"
        iyz="1.6388E-19"
        izz="0.13119" />
    </inertial>
    <visual>
      <origin
        xyz="0 0 0"
        rpy="0 0 0" />
      <geometry>
        <mesh
          filename="package://Conceptual Mechanism Assembly2/meshes/vertical.STL" />
      </geometry>
      <material
        name="">
        <color
          rgba="0.79216 0.81961 0.93333 1" />
      </material>
    </visual>
    <collision>
      <origin
        xyz="0 0 0"
        rpy="0 0 0" />
      <geometry>
        <mesh
          filename="package://Conceptual Mechanism Assembly2/meshes/vertical.STL" />
      </geometry>
    </collision>
  </link>
  <joint
    name="vertical"
    type="fixed">
    <origin
      xyz="-0.0705 -0.063677 -0.015"
      rpy="1.5708 0 -0.83621" />
    <parent
      link="base_link" />
    <child
      link="vertical" />
    <axis
      xyz="0 0 0" />
  </joint>
  <link
    name="tool_post">
    <inertial>
      <origin
        xyz="-0.0081796 0.023657 -0.0010285"
        rpy="0 0 0" />
      <mass
        value="0.25437" />
      <inertia
        ixx="0.0001431"
        ixy="-8.0319E-08"
        ixz="2.1689E-06"
        iyy="0.00022245"
        iyz="3.3613E-08"
        izz="0.00028062" />
    </inertial>
    <visual>
      <origin
        xyz="0 0 0"
        rpy="0 0 0" />
      <geometry>
        <mesh
          filename="package://Conceptual Mechanism Assembly2/meshes/tool_post.STL" />
      </geometry>
      <material
        name="">
        <color
          rgba="0.79216 0.81961 0.93333 1" />
      </material>
    </visual>
    <collision>
      <origin
        xyz="0 0 0"
        rpy="0 0 0" />
      <geometry>
        <mesh
          filename="package://Conceptual Mechanism Assembly2/meshes/tool_post.STL" />
      </geometry>
    </collision>
  </link>
  <joint
    name="tool_post"
    type="prismatic">
    <origin
      xyz="0.04 0.36659 0"
      rpy="0 0 0" />
    <parent
      link="vertical" />
    <child
      link="tool_post" />
    <axis
      xyz="0 1 0" />
    <limit
      lower="0"
      upper="0"
      effort="0"
      velocity="0" />
  </joint>
  <link
    name="tool_link">
    <inertial>
      <origin
        xyz="-0.012372 -0.010349 -0.0017822"
        rpy="0 0 0" />
      <mass
        value="0.00045027" />
      <inertia
        ixx="3.2618E-09"
        ixy="-3.8961E-24"
        ixz="-4.3493E-09"
        iyy="3.5791E-08"
        iyz="-3.1579E-25"
        izz="3.2829E-08" />
    </inertial>
    <visual>
      <origin
        xyz="0 0 0"
        rpy="0 0 0" />
      <geometry>
        <mesh
          filename="package://Conceptual Mechanism Assembly2/meshes/tool_link.STL" />
      </geometry>
      <material
        name="">
        <color
          rgba="0.79216 0.81961 0.93333 1" />
      </material>
    </visual>
    <collision>
      <origin
        xyz="0 0 0"
        rpy="0 0 0" />
      <geometry>
        <mesh
          filename="package://Conceptual Mechanism Assembly2/meshes/tool_link.STL" />
      </geometry>
    </collision>
  </link>
  <joint
    name="tool_link"
    type="continuous">
    <origin
      xyz="0.044107 0.03225 -0.026607"
      rpy="0 -0.69766 0" />
    <parent
      link="tool_post" />
    <child
      link="tool_link" />
    <axis
      xyz="0 1 0" />
  </joint>
  <link
    name="tool">
    <inertial>
      <origin
        xyz="-0.0055 -0.011607 -0.0081597"
        rpy="0 0 0" />
      <mass
        value="0.00085306" />
      <inertia
        ixx="9.869E-08"
        ixy="-2.903E-10"
        ixz="-2.1453E-08"
        iyy="1.6478E-07"
        iyz="7.3519E-10"
        izz="6.9094E-08" />
    </inertial>
    <visual>
      <origin
        xyz="0 0 0"
        rpy="0 0 0" />
      <geometry>
        <mesh
          filename="package://Conceptual Mechanism Assembly2/meshes/tool.STL" />
      </geometry>
      <material
        name="">
        <color
          rgba="0.79216 0.81961 0.93333 1" />
      </material>
    </visual>
    <collision>
      <origin
        xyz="0 0 0"
        rpy="0 0 0" />
      <geometry>
        <mesh
          filename="package://Conceptual Mechanism Assembly2/meshes/tool.STL" />
      </geometry>
    </collision>
  </link>
  <joint
    name="tool"
    type="fixed">
    <origin
      xyz="-0.05189 0.00275 0.0029686"
      rpy="3.1416 -0.69766 -3.1416" />
    <parent
      link="tool_link" />
    <child
      link="tool" />
    <axis
      xyz="0 0 0" />
  </joint>
</robot>